Traceback (most recent call last):
  File "C:\Users\Vishal\AppData\Local\Programs\Python\Python310\lib\site-packages\jupyter_cache\executors\utils.py", line 58, in single_nb_execution
    executenb(
  File "C:\Users\Vishal\AppData\Local\Programs\Python\Python310\lib\site-packages\nbclient\client.py", line 1305, in execute
    return NotebookClient(nb=nb, resources=resources, km=km, **kwargs).execute()
  File "C:\Users\Vishal\AppData\Local\Programs\Python\Python310\lib\site-packages\jupyter_core\utils\__init__.py", line 166, in wrapped
    return loop.run_until_complete(inner)
  File "C:\Users\Vishal\AppData\Local\Programs\Python\Python310\lib\asyncio\base_events.py", line 646, in run_until_complete
    return future.result()
  File "C:\Users\Vishal\AppData\Local\Programs\Python\Python310\lib\site-packages\nbclient\client.py", line 705, in async_execute
    await self.async_execute_cell(
  File "C:\Users\Vishal\AppData\Local\Programs\Python\Python310\lib\site-packages\nbclient\client.py", line 1058, in async_execute_cell
    await self._check_raise_for_error(cell, cell_index, exec_reply)
  File "C:\Users\Vishal\AppData\Local\Programs\Python\Python310\lib\site-packages\nbclient\client.py", line 914, in _check_raise_for_error
    raise CellExecutionError.from_cell_and_msg(cell, exec_reply_content)
nbclient.exceptions.CellExecutionError: An error occurred while executing the following cell:
------------------
import xgboost as xgb

# Convert the training data to DMatrix format
dtrain = xgb.DMatrix(X_train, label=y_train)

# Set the parameters for the XGBoost model
params = {
    'objective': 'reg:squarederror',
    'n_estimators': 500,
    'max_depth': 4,
    'min_child_weight': 10,
    'learning_rate': 0.05,
    'subsample': 0.5,
    'colsample_bytree': 0.8,
    'verbosity': 2
}

# Create the XGBoost regressor
xgbr = xgb.XGBRegressor(**params)

# Train the XGBoost model
xgbr.fit(X_train, y_train)

# Print the model summary
print(xgbr)
------------------


[1;31m---------------------------------------------------------------------------[0m
[1;31mModuleNotFoundError[0m                       Traceback (most recent call last)
Input [1;32mIn [11][0m, in [0;36m<cell line: 1>[1;34m()[0m
[1;32m----> 1[0m [38;5;28;01mimport[39;00m [38;5;21;01mxgboost[39;00m [38;5;28;01mas[39;00m [38;5;21;01mxgb[39;00m
[0;32m      3[0m [38;5;66;03m# Convert the training data to DMatrix format[39;00m
[0;32m      4[0m dtrain [38;5;241m=[39m xgb[38;5;241m.[39mDMatrix(X_train, label[38;5;241m=[39my_train)

[1;31mModuleNotFoundError[0m: No module named 'xgboost'

