Traceback (most recent call last):
  File "C:\Users\Vishal\AppData\Local\Programs\Python\Python310\lib\site-packages\jupyter_cache\executors\utils.py", line 58, in single_nb_execution
    executenb(
  File "C:\Users\Vishal\AppData\Local\Programs\Python\Python310\lib\site-packages\nbclient\client.py", line 1305, in execute
    return NotebookClient(nb=nb, resources=resources, km=km, **kwargs).execute()
  File "C:\Users\Vishal\AppData\Local\Programs\Python\Python310\lib\site-packages\jupyter_core\utils\__init__.py", line 166, in wrapped
    return loop.run_until_complete(inner)
  File "C:\Users\Vishal\AppData\Local\Programs\Python\Python310\lib\asyncio\base_events.py", line 646, in run_until_complete
    return future.result()
  File "C:\Users\Vishal\AppData\Local\Programs\Python\Python310\lib\site-packages\nbclient\client.py", line 705, in async_execute
    await self.async_execute_cell(
  File "C:\Users\Vishal\AppData\Local\Programs\Python\Python310\lib\site-packages\nbclient\client.py", line 1058, in async_execute_cell
    await self._check_raise_for_error(cell, cell_index, exec_reply)
  File "C:\Users\Vishal\AppData\Local\Programs\Python\Python310\lib\site-packages\nbclient\client.py", line 914, in _check_raise_for_error
    raise CellExecutionError.from_cell_and_msg(cell, exec_reply_content)
nbclient.exceptions.CellExecutionError: An error occurred while executing the following cell:
------------------
from google.colab import files
uploaded = files.upload()

csv_file = "Formatted_ETAS_Output.csv"

# Read the CSV file using Pandas
df = pd.read_csv(csv_file, sep=',', lineterminator='\n')

# # Access the data in the DataFrame

------------------


[1;31m---------------------------------------------------------------------------[0m
[1;31mModuleNotFoundError[0m                       Traceback (most recent call last)
Input [1;32mIn [4][0m, in [0;36m<cell line: 1>[1;34m()[0m
[1;32m----> 1[0m [38;5;28;01mfrom[39;00m [38;5;21;01mgoogle[39;00m[38;5;21;01m.[39;00m[38;5;21;01mcolab[39;00m [38;5;28;01mimport[39;00m files
[0;32m      2[0m uploaded [38;5;241m=[39m files[38;5;241m.[39mupload()
[0;32m      4[0m csv_file [38;5;241m=[39m [38;5;124m"[39m[38;5;124mFormatted_ETAS_Output.csv[39m[38;5;124m"[39m

[1;31mModuleNotFoundError[0m: No module named 'google'

